<?xml version="1.0"?>
  <robot name = "ratatosk">
    <link name="base_link">

      <visual>
        <geometry>
          <mesh filename = "package://ratatosk_description/meshes/chassis_centered.stl" scale="0.001 0.001 0.001"/>
        </geometry>
	<material name="white">
	  <color rgba="1 1 1 1"/>
	</material>
      </visual>

      <inertial>
        <mass value = "10"/>
        <inertia ixx="0.1" ixy="0" ixz="0" iyy="0.1" iyz="0" izz="0.1"/>
      </inertial>

      <collision>
        <geometry>
          <cylinder radius = "0.0825" length = "0.035"/>
        </geometry>
      </collision>

      <collision>
        <origin xyz="0 -0.045 -0.022"/>
        <geometry>0.04
          <sphere radius = "0.0125"/>
        </geometry>
      </collision>

      <collision>
        <origin xyz="0 0.065 -0.022"/>
        <geometry>
          <sphere radius = "0.0125"/>
        </geometry>
      </collision>

    </link>

    <link name="wheel_l">

      <visual>
        <geometry>
          <mesh filename = "package://ratatosk_description/meshes/wheel_centered.stl" scale="0.001 0.001 0.001"/>
        </geometry>
      </visual>

      <inertial>
        <mass value = "0.03"/>
        <inertia ixx="0.1" ixy="0" ixz="0" iyy="0.1" iyz="0" izz="0.1"/>
      </inertial>

      <collision>
        <origin xyz="-0.0025 0 0" rpy="0 1.571 0"/>
        <geometry>
          <cylinder radius = "0.037" length = "0.008"/>
        </geometry>
      </collision>

    </link>

    <link name="wheel_r">

      <visual>
        <geometry>
          <mesh filename = "package://ratatosk_description/meshes/wheel_centered.stl" scale="0.001 0.001 0.001"/>
        </geometry>
      </visual>

      <inertial>
        <mass value = "0.03"/>
        <inertia ixx="0.1" ixy="0" ixz="0" iyy="0.1" iyz="0" izz="0.1"/>
      </inertial>

      <collision>
        <origin xyz="-0.0025 0 0" rpy="0 1.571 0"/>
        <geometry>
          <cylinder radius = "0.037" length = "0.008"/>
        </geometry>
      </collision>

    </link>

    <link name="laser">
	
	<visual>
	   <geometry>
	     <cylinder radius="0.001" length="0.0005"/>
	   </geometry>
	</visual>

      <inertial>
        <mass value = "0"/>
        <inertia ixx="0" ixy="0" ixz="0" iyy="0" iyz="0" izz="0"/>
      </inertial>

	<collision>
	   <origin xyz="0 0 0.05"/>
	   <geometry>
	     <cylinder radius="0.001" length="0.0005"/>
	   </geometry>
	</collision>

    </link>

<!-- End of Links -->

    <joint name="wheel_l_joint" type="continuous">
      <origin xyz="-0.068 0 0"/>
      <axis xyz="1 0 0"/>
      <parent link = "base_link"/>
      <child link = "wheel_l"/>
    </joint>

    <joint name="wheel_r_joint" type="continuous">
      <origin xyz="0.068 0 0" rpy="0 3.14 0"/>
      <axis xyz="-1 0 0"/>
      <parent link = "base_link"/>
      <child link = "wheel_r"/>
    </joint>

    <joint name="laser_joint" type="fixed">
      <origin xyz="0 0 0.05"/>
      <parent link = "base_link"/>
      <child link = "laser"/>
    </joint>

<!-- End of Joint -->

<transmission name="wheel_l_transmission">
  <type>transmission_interface/SimpleTransmission</type>
  <joint name="wheel_l_joint">
    <hardwareInterface>hardware_interface/VelocityJointInterface</hardwareInterface>
  </joint>
  <actuator name="wheel_l_motor">
    <mechanicalReduction>1</mechanicalReduction>
    <hardwareInterface>hardware_interface/VelocityJointInterface</hardwareInterface>
  </actuator>
</transmission>

<transmission name="wheel_r_transmission">
  <type>transmission_interface/SimpleTransmission</type>
  <joint name="wheel_r_joint">
    <hardwareInterface>hardware_interface/VelocityJointInterface</hardwareInterface>
  </joint>
  <actuator name="wheel_r_motor">
    <mechanicalReduction>1</mechanicalReduction>
    <hardwareInterface>hardware_interface/VelocityJointInterface</hardwareInterface>
  </actuator>
</transmission>

<!-- End of Transmission -->

    <gazebo>
        <plugin name="gazebo_ros_control" filename="libgazebo_ros_control.so">
            <robotSimType>gazebo_ros_control/DefaultRobotHWSim</robotSimType>
        </plugin>
    </gazebo>

    <gazebo reference="laser">
	<sensor type="ray" name="hokuyo_sensor">
	   <pose>0 0 0 0 0 0</pose>
	   <visualize>false</visualize>
	   <update_rate>40</update_rate>
	   <ray>
	      <scan>
		<horizontal>
		   <samples>720</samples>
		   <resolution>1</resolution>
		   <min_angle>-0.349066</min_angle>
		   <max_angle>3.490659</max_angle>
		</horizontal>
	      </scan>
	      <range>
		<min>0.10</min>
		<max>30.0</max>
		<resolution>0.01</resolution>
	      </range>
	      <noise>
		<type>gaussian</type>
		<mean>0.0</mean>
		<stddev>0.01</stddev>
	      </noise>
	   </ray>
	   <plugin name="gazebo_ros_hokuyo_sensor_controller" filename="libgazebo_ros_laser.so">
		<topicName>/scan</topicName>
		<frameName>laser</frameName>
	   </plugin>
	</sensor>
    </gazebo>

<!-- End of Gazebo -->

<!-- Use lidar with small angle to mimic IR sensor -->
<!-- Look into conver lidar message into range message for readability -->
<!-- Example of lidar simulation is on Cappybot -->

  </robot>
